<?xml version="1.0"?>
<robot name="WuKong">
	<link name="body">
		<visual>
			<geometry>
				<box size="0.2 0.3 0.8"/>
			</geometry>
			<material name="TecBlue">
				<color rgba="0.02 0.15 0.69 0.8"/>
		      	</material>
			<origin xyz="0 0 0.4" />
		</visual>
	</link>

	<joint name="ShoulderPitch" type="continuous">
		<parent link="body" />
		<child link="Shoulder" />
		<axis xyz="0 1 0"/>
		<origin xyz="0 -0.15 0.7"/>
	</joint>

	<link name="Shoulder">
 		<visual>
		      <geometry>
				<mesh filename="package://wukong/meshes/Shoulder.STL" />
		      </geometry>
		      <material name="TecBlue" />
		      <origin rpy="0 0 0" xyz="0 0 0"/>
    		</visual>
	</link>

	<joint name="ShoulderRoll" type="continuous">
		<parent link="Shoulder" />
		<child link="UpperArm1" />
		<axis xyz="1 0 0"/>
		<origin xyz="0 -0.13395 0"/>
	</joint>

	<link name="UpperArm1">
		<visual>
		      <geometry>
				<mesh filename="package://wukong/meshes/UpperArm1.STL" />
		      </geometry>
		      <material name="TecBlue" />
			<origin rpy="0 0 0" xyz="0 0 0"/>
    		</visual>
	</link>
	
	<joint name="ShoulderYaw" type="continuous">
		<parent link="UpperArm1" />
		<child link="UpperArm2" />
		<axis xyz="0 0 1"/>
		<origin xyz="0 0 -0.035"/>
	</joint>

	<link name="UpperArm2">
		<visual>
		      <geometry>
				<mesh filename="package://wukong/meshes/UpperArm2.STL" />
		      </geometry>
		      <material name="TecBlue" />
			<origin rpy="0 0 0" xyz="0 0 0"/>
    		</visual>
	</link>

	<joint name="ElbowRoll" type="continuous">
		<parent link="UpperArm2" />
		<child link="LowerArm1" />
		<axis xyz="1 0 0"/>
		<origin xyz="0 0 -0.221"/>
	</joint>
	
	<link name="LowerArm1">
		<visual>
			<geometry>
				<mesh filename="package://wukong/meshes/LowerArm1.STL" />
			</geometry>
			<material name="TecBlue" />
			<origin rpy="0 0 0" xyz="0 0 0"/>
    		</visual>
	</link>

	<joint name="ElbowYaw" type="continuous">
		<parent link="LowerArm1" />
		<child link="LowerArm2" />
		<axis xyz="0 0 1"/>
		<origin xyz="0 0 -0.0606"/>
	</joint>

	<link name="LowerArm2">
		<visual>
		      <geometry>
				  <mesh filename="package://wukong/meshes/LowerArm2.STL" />
		      </geometry>
		      <material name="TecBlue" />
			<origin rpy="0 0 0" xyz="0 0 0"/>
    		</visual>
	</link>
	
	<joint name="WristRoll" type="continuous">
		<parent link="LowerArm2" />
		<child link="LowerArm3" />
		<axis xyz="1 0 0"/>
		<origin xyz="0 0 -0.19908"/>
	</joint>

	<link name="LowerArm3">
		<visual>
		      <geometry>
				<mesh filename="package://wukong/meshes/LowerArm3.STL" />
		      </geometry>
		      <material name="TecBlue" />
			  <origin rpy="0 0 0" xyz="0 0 0"/>
    		</visual>
	</link>

	<joint name="WristPitch" type="continuous">
		<parent link="LowerArm3" />
		<child link="Racket" />
		<axis xyz="0 1 0"/>
		<origin xyz="0 0 0"/>
	</joint>

	<link name="Racket">
		<visual>
		      <geometry>
				<mesh filename="package://wukong/meshes/Racket.STL" />
		      </geometry>
		     <material name="TecBlue" />
			<origin rpy="0 0 0" xyz="0 -0.032 0"/>
    		</visual>
	</link>

</robot>
