jjj<?xml version="1.0"?>
<robot name="qixing">
	<link name="base_link">
		<visual>			
			<geometry>
				<cylinder length="0.14" radius="0.05"/>
			</geometry>
			<origin rpy="3.14 0 0" xyz="0 0 0.07"/>
			<material name="abb_origin">
				<color	rgba="1 0.43 0 1" />
			</material>	
		</visual>
		<collision>
			<geometry>
				<cylinder length="0.14" radius="0.05"/>
			</geometry>
			<origin rpy="3.14 0 0 " xyz="0 0 0.07"/>
		</collision>
	</link>

	<joint name="joint1" type="continuous">
		<parent link="base_link" />
		<child link="link1" />
		<axis xyz="0 0 1" />
		<origin xyz="0 0 0.14" />
	</joint>

	<link name="link1">
		<visual>
			<geometry>
				<cylinder length="0.12" radius="0.04"/>
			</geometry>
			<origin xyz="0 0 0.06" />
			<material name="abb_origin" />	
		</visual>
		<collision>
			<geometry>
				<cylinder length="0.12" radius="0.04"/>
			</geometry>
			<origin xyz="0 0 0.06" />
		</collision>
	</link>

	<joint name="joint2" type="continuous">
		<parent link="link1" />
		<child link="link2" />
		<axis xyz="0 1 0" />
		<origin xyz="0 0 0.12" />
	</joint>

	<link name="link2">
		<visual>
			<geometry>
				<cylinder length="0.4" radius="0.03" />
			</geometry>
			<origin xyz="0 0 0.2" />
			<material name="abb_origin" />
		</visual>
		<collision>
			<geometry>
				<cylinder length="0.4" radius="0.03" />
			</geometry>
			<origin xyz="0 0 0.2" />
		</collision>
	</link>

	<joint name="joint3" type="continuous">
		<parent link="link2" />
		<child link="link3" />
		<axis xyz="0 1 0" />
		<origin xyz="0 0 0.4" />
	</joint>	

	<link name="link3">
		<visual>
			<geometry>
				<cylinder length="0.26" radius="0.025" />
			</geometry>
			<origin xyz="0 0 0.13" />
			<material name="abb_origin" />
		</visual>
		<collision>
			<geometry>
				<cylinder length="0.26" radius="0.025" />
			</geometry>
			<origin xyz="0 0 0.13" />
		</collision>
	</link>

	<joint name="joint4" type="continuous">
		<parent link="link3" />
		<child link="link4" />
		<axis xyz="0 0 1" />
		<origin xyz="0 0 0.26" />
	</joint>

	<link name="link4">
		<visual>
			<geometry>
				<cylinder length="0.1" radius="0.02" />
			</geometry>
			<origin xyz="0 0 0.05" />
			<material name="abb_origin" />
		</visual>
		<collision>
			<geometry>
				<cylinder length="0.1" radius="0.02" />
			</geometry>
			<origin xyz="0 0 0.05" />
		</collision>
	</link>

	<joint name="joint5" type="continuous">
		<parent link="link4" />
		<child link="link5" />
		<axis xyz="0 1 0" />
		<origin xyz="0 0 0.1" />
	</joint>

	<link name="link5">
		<visual>
			<geometry>
				<cylinder length="0.16" radius="0.015" />
			</geometry>
			<origin xyz="0 0 0.08" />
			<material name="abb_origin" />
		</visual>
		<collision>
			<geometry>
				<cylinder length="0.16" radius="0.015" />
			</geometry>
			<origin xyz="0 0 0.08" />
		</collision>
	</link>

	<joint name="joint6" type="continuous">
		<parent link="link5" />
		<child link="link6" />
		<axis xyz="0 0 1" />
		<origin xyz="0 0 0.16" />
	</joint>
	 
	<link name="link6">
		<visual>
			<geometry>
				<cylinder length="0.025" radius="0.01" />
			</geometry>
			<origin xyz="0 0 0.0125" />
			<material name="abb_origin" />
		</visual>
		<collision>
			<geometry>
				<cylinder length="0.025" radius="0.01" />
			</geometry>
			<origin xyz="0 0 0.0125" />
		</collision>
	</link>
</robot>



